Workbook

Sheet Index
A1: Global Development Indicators
A2: Comparative Analysis of 15 Economies, 2000–2024
A4: Workbook Navigation
A5: Section | B5: Sheet Name | C5: Description
A6: Source Data | B6: WorldBankRaw | C6: Original World Bank data.
A7: Source Data | B7: Data | C7: Original World Bank download in wide format.
A8: Metadata | B8: Series - Metadata | C8: Definitions and metadata for the selected indicators.
A9: Processed Data | B9: Clean_Data | C9: Cleaned dataset of 375 country-year records.
A10: Analysis | B10: Analysis | C10: 2024 comparison across 15 economies.
A11: Analysis | B11: Historical_Analysis | C11: Historical indicator tables covering 2000–2024 for five selected economies.
A12: Visualisation | B12: Dashboard | C12: Visual comparison of four development indicators across five selected economies, 2000–2024.
A13: Analysis | B13: Pivot_Table | C13: Summary tables for comparing indicators.
A14: Documentation | B14: Data_Dictionary | C14: Variable definitions, units, and sources.

Sheet WorldBankRaw
A1: Country Name | B1: Country Code | C1: Year | D1: GDP per capita (current US$) | E1: Inflation, consumer prices (annual %) | F1: Unemployment, total (% of total labor force) (modeled ILO estimate) | G1: Population, total
A2: Brazil | B2: BRA | C2: 2000 | D2: 3766.5481 | E2: 7.0441411 | F2: 10.889 | G2: 174018282
A3: Brazil | B3: BRA | C3: 2001 | D3: 3176.2894 | E3: 6.840359 | F3: 10.649 | G3: 176301203
A4: Brazil | B4: BRA | C4: 2002 | D4: 2855.9402 | E4: 8.4501644 | F4: 10.641 | G4: 178503484
A5: Brazil | B5: BRA | C5: 2003 | D5: 3090.607 | E5: 14.71492 | F5: 11.168 | G5: 180622688
A6: Brazil | B6: BRA | C6: 2004 | D6: 3663.8232 | E6: 6.5971851 | F6: 10.072 | G6: 182675143
A7: Brazil | B7: BRA | C7: 2005 | D7: 4827.7817 | E7: 6.8695372 | F7: 10.551 | G7: 184688101
A8: Brazil | B8: BRA | C8: 2006 | D8: 5934.1447 | E8: 4.1835681 | F8: 9.692 | G8: 186653106
A9: Brazil | B9: BRA | C9: 2007 | D9: 7409.6913 | E9: 3.641273 | F9: 9.28 | G9: 188552320
A10: Brazil | B10: BRA | C10: 2008 | D10: 8908.3318 | E10: 5.6785939 | F10: 8.268 | G10: 190367302
A11: Brazil | B11: BRA | C11: 2009 | D11: 8678.6592 | E11: 4.8880348 | F11: 9.419 | G11: 192079951
A12: Brazil | B12: BRA | C12: 2010 | D12: 11403.282 | E12: 5.0387269 | F12: 8.42 | G12: 193701929
A13: Brazil | B13: BRA | C13: 2011 | D13: 13396.624 | E13: 6.6364496 | F13: 7.578 | G13: 195284734
... A376: United States | B376: USA | C376: 2024 | D376: 86169.664 | E376: 2.9495252 | F376: 4.022 | G376: 340003797

Sheet Data
A1: Country Name | B1: Country Code | C1: Series Name | D1: Series Code | E1: 2000 [YR2000] | F1: 2001 [YR2001] | G1: 2002 [YR2002] | H1: 2003 [YR2003] | I1: 2004 [YR2004] | J1: 2005 [YR2005] | K1: 2006 [YR2006] | L1: 2007 [YR2007] | M1: 2008 [YR2008] | N1: 2009 [YR2009] | O1: 2010 [YR2010] | P1: 2011 [YR2011] | Q1: 2012 [YR2012] | R1: 2013 [YR2013] | S1: 2014 [YR2014] | T1: 2015 [YR2015] | U1: 2016 [YR2016] | V1: 2017 [YR2017] | W1: 2018 [YR2018] | X1: 2019 [YR2019] | Y1: 2020 [YR2020] | Z1: 2021 [YR2021] | AA1: 2022 [YR2022] | AB1: 2023 [YR2023] | AC1: 2024 [YR2024]
A2: India | B2: IND | C2: GDP per capita (current US$) | D2: NY.GDP.PCAP.CD | E2: 442.75022 | F2: 450.3579 | G2: 469.14993 | H2: 544.14313 | I2: 624.25883 | J2: 710.48808 | K2: 801.66835 | L2: 1021.8871 | M2: 992.51958 | N2: 1094.9497 | O2: 1347.5194 | P2: 1445.4613 | Q2: 1429.322 | R2: 1432.844 | S2: 1553.884 | T2: 1583.9982 | U2: 1707.5089 | V2: 1950.1047 | W2: 1966.2546 | X2: 2041.4286 | Y2: 1907.0425 | Z2: 2239.6138 | AA2: 2279.9815 | AB2: 2434.4483 | AC2: 2591.9917
A3: India | B3: IND | C3: Inflation, consumer prices (annual %) | D3: FP.CPI.TOTL.ZG | E3: 4.0094359 | F3: 3.7792931 | G3: 4.297152 | H3: 3.805859 | I3: 3.7672517 | J3: 4.2463436 | K3: 5.7965234 | L3: 6.3728814 | M3: 8.349267 | N3: 10.882353 | O3: 11.98939 | P3: 8.9117934 | Q3: 9.4789969 | R3: 10.017878 | S3: 6.6656567 | T3: 4.9069734 | U3: 4.9482163 | V3: 3.3281734 | W3: 3.9388265 | X3: 3.7295057 | Y3: 6.6234368 | Z3: 5.1314075 | AA3: 6.6990341 | AB3: 5.6491432 | AC3: 4.9530355
A4: India | B4: IND | C4: Unemployment, total (% of total labor force) (modeled ILO estimate) | D4: SL.UEM.TOTL.ZS | E4: 7.589 | F4: 7.611 | G4: 7.681 | H4: 7.633 | I4: 7.598 | J4: 7.551 | K4: 7.553 | L4: 7.562 | M4: 7.629 | N4: 7.636 | O4: 7.631 | P4: 7.609 | Q4: 7.645 | R4: 7.678 | S4: 7.656 | T4: 7.629 | U4: 7.611 | V4: 7.626 | W4: 7.652 | X4: 6.51 | Y4: 7.859 | Z4: 6.38 | AA4: 4.822 | AB4: 4.172 | AC4: 4.173
A5: India | B5: IND | C5: Population, total | D5: SP.POP.TOTL | E5: 1057922733 | F5: 1077898575 | G5: 1097600380 | H5: 1116803006 | I5: 1135991513 | J5: 1154676322 | K5: 1172878890 | L5: 1190676021 | M5: 1207930964 | N5: 1225524753 | O5: 1243481564 | P5: 1261224954 | Q5: 1278674502 | R5: 1295829511 | S5: 1312277191 | T5: 1328024498 | U5: 1343944296 | V5: 1359657400 | W5: 1374659064 | X5: 1389030312 | Y5: 1402617695 | Z5: 1414203896 | AA5: 1425423212 | AB5: 1438069596 | AC5: 1450935791
A6: United States | B6: USA | C6: GDP per capita (current US$) | D6: NY.GDP.PCAP.CD | E6: 36329.97 | F6: 37133.62 | G6: 37997.742 | H6: 39490.302 | I6: 41724.641 | J6: 44123.4 | K6: 46301.988 | L6: 48050.227 | M6: 48570.059 | N6: 47194.95 | O6: 48642.631 | P6: 50024.881 | Q6: 51708.394 | R6: 53297.386 | S6: 55153.394 | T6: 56849.47 | U6: 57976.628 | V6: 60047.719 | W6: 62875.666 | X6: 65227.957 | Y6: 64465.297 | Z6: 71441.232 | AA6: 78008.69 | AB6: 82586.785 | AC6: 86169.664
A7: United States | B7: USA | C7: Inflation, consumer prices (annual %) | D7: FP.CPI.TOTL.ZG | E7: 3.3768573 | F7: 2.8261711 | G7: 1.5860316 | H7: 2.270095 | I7: 2.6772367 | J7: 3.3927468 | K7: 3.2259441 | L7: 2.8526725 | M7: 3.8391003 | N7: -0.35554627 | O7: 1.6400434 | P7: 3.1568416 | Q7: 2.0693373 | R7: 1.4648327 | S7: 1.622223 | T7: 0.11862714 | U7: 1.2615832 | V7: 2.13011 | W7: 2.4425833 | X7: 1.8122101 | Y7: 1.2335844 | Z7: 4.6978589 | AA7: 8.0027998 | AB7: 4.1163384 | AC7: 2.9495252
A8: United States | B8: USA | C8: Unemployment, total (% of total labor force) (modeled ILO estimate) | D8: SL.UEM.TOTL.ZS | E8: 3.992 | F8: 4.731 | G8: 5.783 | H8: 5.989 | I8: 5.529 | J8: 5.084 | K8: 4.623 | L8: 4.622 | M8: 5.784 | N8: 9.254 | O8: 9.633 | P8: 8.949 | Q8: 8.069 | R8: 7.375 | S8: 6.168 | T8: 5.28 | U8: 4.869 | V8: 4.355 | W8: 3.896 | X8: 3.669 | Y8: 8.055 | Z8: 5.349 | AA8: 3.65 | AB8: 3.638 | AC8: 4.022
A9: United States | B9: USA | C9: Population, total | D9: SP.POP.TOTL | E9: 282162411 | F9: 284968955 | G9: 287625193 | H9: 290107933 | I9: 292805298 | J9: 295516599 | K9: 298379912 | L9: 301231207 | M9: 304093966 | N9: 306771529 | O9: 309378227 | P9: 311839461 | Q9: 314339099 | R9: 316726282 | S9: 319257560 | T9: 321815121 | U9: 324353340 | V9: 326608609 | W9: 328529577 | X9: 330226227 | Y9: 331578104 | Z9: 332100166 | AA9: 333996304 | AB9: 336755052 | AC9: 340003797
A10: Germany | B10: DEU | C10: GDP per capita (current US$) | D10: NY.GDP.PCAP.CD | E10: 23925.856 | F10: 23878.364 | G10: 25486.594 | H10: 30711.102 | I10: 34566.736 | J10: 35084.436 | K10: 36980.335 | L10: 42350.922 | M10: 46379.165 | N10: 42471.887 | O10: 42396.967 | P10: 47630.976 | Q10: 44718.016 | R10: 47206.835 | S10: 48959.599 | T10: 41929.755 | U10: 42948.938 | V10: 45553.934 | W10: 48916.169 | X10: 47656.2 | Y10: 47394.873 | Z10: 52349.246 | AA10: 50506.518 | AB10: 54776.767 | AC10: 56103.732
A11: Germany | B11: DEU | C11: Inflation, consumer prices (annual %) | D11: FP.CPI.TOTL.ZG | E11: 1.4402684 | F11: 1.9838573 | G11: 1.4208062 | H11: 1.0342222 | I11: 1.665737 | J11: 1.5469111 | K11: 1.5774264 | L11: 2.298344 | M11: 2.6283798 | N11: 0.31273901 | O11: 1.1038104 | P11: 2.0751728 | Q11: 2.0084888 | R11: 1.5047233 | S11: 0.906794 | T11: 0.51442614 | U11: 0.49174701 | V11: 1.5094949 | W11: 1.7321688 | X11: 1.4456598 | Y11: 0.14487793 | Z11: 3.0666667 | AA11: 6.8725744 | AB11: 5.9464367 | AC11: 2.2564981
A12: Germany | B12: DEU | C12: Unemployment, total (% of total labor force) (modeled ILO estimate) | D12: SL.UEM.TOTL.ZS | E12: 7.917 | F12: 7.773 | G12: 8.482 | H12: 9.779 | I12: 10.727 | J12: 11.193 | K12: 10.277 | L12: 8.732 | M12: 7.508 | N12: 7.88 | O12: 7.043 | P12: 5.967 | Q12: 5.372 | R12: 5.316 | S12: 4.979 | T12: 4.612 | U12: 4.104 | V12: 3.781 | W12: 3.384 | X12: 3.163 | Y12: 3.881 | Z12: 3.594 | AA12: 3.137 | AB12: 3.071 | AC12: 3.4
A13: Germany | B13: DEU | C13: Population, total | D13: SP.POP.TOTL | E13: 82211508 | F13: 82349925 | G13: 82488495 | H13: 82534176 | I13: 82516260 | J13: 82469422 | K13: 82376451 | L13: 82266372 | M13: 82110097 | N13: 81902307 | O13: 81776930 | P13: 80274983 | Q13: 80425823 | R13: 80645605 | S13: 80982500 | T13: 81686611 | U13: 82348669 | V13: 82657002 | W13: 82905782 | X13: 83092962 | Y13: 83160871 | Z13: 83196078 | AA13: 83177813 | AB13: 83287273 | AC13: 83516593
... A61: Indonesia | B61: IDN | C61: Population, total | D61: SP.POP.TOTL | E61: 216077790 | F61: 219097902 | G61: 222088495 | H61: 225048008 | I61: 227926649 | J61: 230871650 | K61: 233951652 | L61: 237062337 | M61: 240157903 | N61: 243220028 | O61: 246305322 | P61: 249470032 | Q61: 252698525 | R61: 255852467 | S61: 258877399 | T61: 261799249 | U61: 264627418 | V61: 267346658 | W61: 269951846 | X61: 272489381 | Y61: 274814866 | Z61: 276758053 | AA61: 278830529 | AB61: 281190067 | AC61: 283487931
A65: Data from database: World Development Indicators
A66: Last Updated: 10/08/2026

Sheet Series - Metadata
A1: Code | B1: License Type | C1: Indicator Name | D1: Short definition | E1: Long definition | F1: Source | G1: Topic | H1: Dataset | I1: Unit of measure | J1: Periodicity | K1: Reference period | L1: Aggregation method | M1: Statistical concept and methodology | N1: Development relevance | O1: Limitations and exceptions | P1: Other notes | Q1: License URL
A2: NY.GDP.PCAP.CD | B2: CC BY-4.0 | C2: GDP per capita (current US$) | D2: Gross domestic product is the total income earned through the production of goods and services in an economic territory during an accounting period. It can be measured in three different ways: using either the expenditure approach, the income approach, or the production approach. The core indicator has been divided by the general population to achieve a per capita estimate.This indicator is expressed in current prices, meaning no adjustment has been made to account for price changes over time. This indicator is expressed in United States dollars. | E2: Gross domestic product is the total income earned through the production of goods and services in an economic territory during an accounting period. It can be measured in three different ways: using either the expenditure approach, the income approach, or the production approach. The core indicator has been divided by the general population to achieve a per capita estimate.This indicator is expressed in current prices, meaning no adjustment has been made to account for price changes over time. This indicator is expressed in United States dollars. | F2: Country official statistics, National Statistical Organizations and/or Central Banks; National Accounts data files, Organisation for Economic Co-operation and Development (OECD); Staff estimates, World Bank (WB) | G2: Economic Policy & Debt: National accounts: US$ at current prices: Aggregate indicators | H2: WB_WDI | I2: Current US$ | J2: Annual | K2: 1960-2025 | L2: Weighted average | M2: Methodology: National accounts are compiled in accordance with international standards: System of National Accounts, 2008 or 1993 versions. Specific information on how countries compile their national accounts can be found on the IMF website: https://dsbb.imf.org/ Per capita estimates are divided by the total population. Statistical concept(s): The conceptual elements of the SNA (System of National Accounts) measure what takes place in the economy, between which agents, and for what purpose. At the heart of the SNA is the production of goods and services. These may be used for consumption in the period to which the accounts relate or may be accumulated for use in a later period. In simple terms, the amount of value added generated by production represents GDP. The income corresponding to GDP is distributed to the various agents or groups of agents as income and it is the process of distributing and redistributing income that allows one agent to consume the goods and services produced by another agent or to acquire goods and services for later consumption. The way in which the SNA captures this pattern of economic flows is to identify the activities concerned by recognizing the institutional units in the economy and by specifying the structure of accounts capturing the transactions relevant to one stage or another of the process by which goods and services are produced and ultimately consumed. | N2: This indicator is related to the national accounts, which are critical for understanding and managing a country's economy. They provide a framework for the analysis of economic performance. National accounts are the basis for estimating the Gross Domestic Product (GDP) and Gross National Income (GNI), which are the most widely used indicator of economic performance. They are essential for government policymakers, providing the data needed to design and assess fiscal and monetary policies; and are also used by businesses and investors to assess the economic climate and make investment decisions. NAS enable comparison between economies, which is crucial for international trade, investment decisions, and economic competitiveness. More specifically, this indicator is related to national accounts aggregates. Gross Domestic Product (GDP), Gross National Income (GNI), and other aggregates provide a snapshot of the size and health of an economy by measuring the total economic activity within a country. They can thus be used by policymakers to design and implement economic policies, as they reflect the overall economic performance and can indicate the need for intervention in certain areas. Aggregates also allow for comparisons between different economies, which can be useful for trade negotiations, investment decisions, and economic benchmarking. By examining aggregates over time, economists and analysts can identify trends, cycles, and potential areas of concern within an economy, and investors can use national accounts aggregates to assess the potential risks and returns of investing in a particular country. Overall, national accounts aggregates are fundamental tools for economic analysis, policy formulation, and decision-making at both the national and international levels. | Q2: https://datacatalog.worldbank.org/public-licenses#cc-by
A3: FP.CPI.TOTL.ZG | B3: CC BY-4.0 | C3: Inflation, consumer prices (annual % growth) | D3: Inflation as measured by the consumer price index reflects the annual percentage change in the cost to the average consumer of acquiring a basket of goods and services that may be fixed or changed at specified intervals, such as yearly. | E3: Inflation as measured by the consumer price index reflects the annual percentage change in the cost to the average consumer of acquiring a basket of goods and services that may be fixed or changed at specified intervals, such as yearly. | F3: International Financial Statistics database, International Monetary Fund (IMF) | G3: Financial Sector: Exchange rates & prices | H3: WB_WDI | I3: % | J3: Annual | K3: 1960-2025 | L3: Median | M3: Methodology: Consumer Prices Indices are compiled in accordance with international standards: Consumer Price Index Manual, 2020 or 2004 version. Specific information on how countries compile their CPI statistics can be found on the IMF website: https://dsbb.imf.org/ Statistical concept(s): The conceptual basis of a consumer price index series is to measure the rate at which prices of consumption goods and services are changing from one period to another. | N3: A general and continuing increase in an economy’s price level is called inflation. The increase in the average prices of goods and services in the economy should be distinguished from a change in the relative prices of individual goods and services. Generally accompanying an overall increase in the price level is a change in the structure of relative prices, but it is only the average increase, not the relative price changes, that constitutes inflation. A commonly used measure of inflation is the consumer price index, which measures the prices of a representative basket of goods and services purchased by a typical household. The consumer price index is usually calculated on the basis of periodic surveys of consumer prices. Other price indices are derived implicitly from indexes of current and constant price series. | Q3: https://datacatalog.worldbank.org/public-licenses#cc-by
A4: SL.UEM.TOTL.ZS | B4: CC BY-4.0 | C4: Unemployment, total (% of total labor force) (modeled ILO estimate) | D4: Unemployment refers to the share of the labor force that is without work but available for and seeking employment. | E4: Unemployment refers to the share of the labor force that is without work but available for and seeking employment. | F4: ILO Modelled Estimates database (ILOEST), International Labour Organization (ILO), uri: https://ilostat.ilo.org/data/bulk/, publisher: ILOSTAT, type: external database, date accessed: January 17, 2026 | G4: Social Protection & Labor: Unemployment | H4: WB_WDI | I4: % of total labor force | J4: Annual | K4: 1991-2025 | L4: Weighted average | M4: Methodology: The unemployment rate is calculated by expressing the number of unemployed persons as a percentage of the total number of persons in the labor force. The labor force (formerly known as the economically active population) is the sum of the number of persons employed and the number of persons unemployed. The series is part of the "ILO modeled estimates database," including nationally reported observations and imputed data for countries with missing data, primarily to capture regional and global trends with consistent country coverage. Country-reported microdata is based mainly on nationally representative labor force surveys, with other sources (e.g., household surveys and population censuses) considering differences in the data source, the scope of coverage, methodology, and other country-specific factors. Country analysis requires caution where limited nationally reported data are available. A series of models are also applied to impute missing observations and make projections. However, imputed observations are not based on national data, are subject to high uncertainty, and should not be used for country comparisons or rankings. For more information: https://ilostat.ilo.org/resources/concepts-and-definitions/ilo-modelled-estimates/ Statistical concept(s): The unemployed comprise all persons of working age who were: a) without work during the reference period, i.e. were not in paid employment or self-employment; b) currently available for work, i.e. were available for paid employment or self-employment during the reference period; and c) seeking work, i.e. had taken specific steps in a specified recent period to seek paid employment or self-employment. Future starters, that is, persons who did not look for work but have a future labor market stake (made arrangements for a future job start) are also counted as unemployed, as are participants in skills training or retraining schemes within employment promotion programs, who on that basis, were “not in employment”, not “currently available” and did not “seek employment” because they had a job offer to start within a short subsequent period generally not greater than three months. The unemployed also include persons “not in employment” who carried out activities to migrate abroad in order to work for pay or profit but who were still waiting for the opportunity to leave. Employment comprises all persons of working age who during a specified brief period, such as one week or one day, were in the following categories: a) paid employment (whether at work or with a job but not at work); or b) self-employment (whether at work or with an enterprise but not at work). The working-age population is the population above the legal working age, but for statistical purposes it comprises all persons above a specified minimum age threshold for which an inquiry on economic activity is made. To promote international comparability, the working-age population is often defined as all persons aged 15 and older, but this may vary from country to country based on national laws and practices (some countries also apply an upper age limit). | N4: The unemployment rate is a useful measure of the underutilization of the labor supply. It reflects the inability of an economy to generate employment for those persons who want to work but are not doing so, even though they are available for employment and actively seeking work. It is thus seen as an indicator of the efficiency and effectiveness of an economy to absorb its labor force and of the performance of the labor market. Given its usefulness in conveying valuable information on a country’s labor market situation and the fact that it is widely recognized as a headline labor market indicator, it was included as one of the indicators to measure progress towards the achievement of the Sustainable Development Goals (SDG), under Goal 8 (Promote sustained, inclusive and sustainable economic growth, full and productive employment and decent work for all). | O4: While the unemployment rate may be considered the most informative labour market indicator, reflecting the general performance of the labour market and the economy as a whole, it should not be interpreted as a measure of economic hardship or of well-being. When based on the internationally-recommended standards, the unemployment rate simply reflects the proportion of the labour force that does not have a job but is available and actively looking for work. It says nothing about the economic resources of unemployed workers or their family members. Its use should, therefore, be limited to serving as a measurement of the utilization of labour and an indication of the failure to find work. Other measures, including income-related indicators, would be needed to evaluate economic hardship. An additional criticism of the aggregate unemployment measure is that it masks information on the composition of the jobless population and therefore misses out on the particularities of the education level, ethnic origin, socio-economic background, work experience, etc. of the unemployed. Moreover, the unemployment rate says nothing about the type of unemployment – whether it is cyclical and short-term or structural and long-term – which is a critical issue for policy makers in the development of their policy responses, especially given that structural unemployment cannot be addressed by boosting market demand only. | P4: National estimates are also available in the WDI database. Caution should be used when comparing ILO estimates with national estimates. | Q4: https://datacatalog.worldbank.org/public-licenses#cc-by
A5: SP.POP.TOTL | B5: CC BY-4.0 | C5: Population, total | D5: Total population is based on the de facto definition of population, which counts all residents regardless of legal status or citizenship. The values shown are midyear estimates. | E5: Total population is based on the de facto definition of population, which counts all residents regardless of legal status or citizenship. The values shown are midyear estimates. | F5: World Population Prospects, United Nations (UN), uri: https://population.un.org/wpp/, publisher: UN Population Division; Statistical databases and publications from national statistical offices, National Statistical Offices (NSOs), uri: https://unstats.un.org/home/nso_sites/, publisher: National Statistical Offices; Eurostat: Demographic Statistics, Eurostat (ESTAT), uri: https://ec.europa.eu/eurostat/data/database?node_code=earn_ses_monthly, publisher: Eurostat; Population and Vital Statistics Report (various years), United Nations (UN), uri: https://unstats.un.org, publisher: UN Statistics Division | G5: Health: Population: Structure | H5: WB_WDI | I5: Unit | J5: Annual | K5: 1960-2025 | L5: Sum | M5: Methodology: Population estimates are usually based on national population censuses, and estimates of fertility, mortality and migration. Errors and undercounting in census occur even in high-income countries. In developing countries errors may be substantial because of limits in the transport, communications, and other resources required to conduct and analyze a full census. The quality and reliability of official demographic data are also affected by public trust in the government, government commitment to full and accurate enumeration, confidentiality and protection against misuse of census data, and census agencies' independence from political influence. Moreover, comparability of population indicators is limited by differences in the concepts, definitions, collection procedures, and estimation methods used by national statistical agencies and other organizations that collect the data. The currentness of a census and the availability of complementary data from surveys or registration systems are objective ways to judge demographic data quality. Some European countries' registration systems offer complete information on population in the absence of a census. The United Nations Statistics Division monitors the completeness of vital registration systems. Some developing countries have made progress over the last 60 years, but others still have deficiencies in civil registration systems. International migration is the only other factor besides birth and death rates that directly determines a country's population change. Estimating migration is difficult. At any time many people are located outside their home country as tourists, workers, or refugees or for other reasons. Standards for the duration and purpose of international moves that qualify as migration vary, and estimates require information on flows into and out of countries that is difficult to collect. One of the major data sources of this indicator is UN Population Division's World Population Prospects, which use the cohort component method to produce population estimates and projections. Population projections, starting from a base year are projected forward using assumptions of mortality, fertility, and migration by age and sex through 2050, based on the UN Population Division's World Population Prospects database medium variant. Statistical concept(s): Estimates of total population describe the size of total population. Population estimates are dependent on the demographic components of change that are fertility, mortality and migration. As the size of population continues to change throughout the time even within a year, a reference time in the year that the estimate refers to is needed, such as mid-year, end-year or beginning of year. The values shown are midyear estimates. | N5: Increases in human population, whether as a result of immigration or more births than deaths, can impact natural resources and social infrastructure. This can place pressure on a country's sustainability. A significant growth in population will negatively impact the availability of land for agricultural production, and will aggravate demand for food, energy, water, social services, and infrastructure. On the other hand, decreasing population size - a result of fewer births than deaths, and people moving out of a country - can impact a government's commitment to maintain services and infrastructure. | O5: Current population estimates for developing countries that lack (i) reliable recent census data, and (ii) pre- and post-census estimates for countries with census data, are provided by the United Nations Population Division and other agencies. The cohort component method - a standard method for estimating and projecting population - requires fertility, mortality, and net migration data, often collected from sample surveys, which can be small or limited in coverage. Population estimates are from demographic modeling and so are susceptible to biases and errors from shortcomings in both the model and the data. Because future trends cannot be known with certainty, population projections have a wide range of uncertainty. | P5: Relevance to gender indicator: disaggregating the population composition by gender will help a country in projecting its demand for social services on a gender basis. | Q5: https://datacatalog.worldbank.org/public-licenses#cc-by

Sheet Clean_Data
A1: Country Name | B1: Country Code | C1: Year | D1: GDP per capita (current US$) | E1: Inflation, consumer prices (annual %) | F1: Unemployment, total (% of total labor force) (modeled ILO estimate) | G1: Population, total
A2: Brazil | B2: BRA | C2: 2000 | D2: 3766.5481 | E2: 7.0441411 | F2: 10.889 | G2: 174018282
A3: Brazil | B3: BRA | C3: 2001 | D3: 3176.2894 | E3: 6.840359 | F3: 10.649 | G3: 176301203
A4: Brazil | B4: BRA | C4: 2002 | D4: 2855.9402 | E4: 8.4501644 | F4: 10.641 | G4: 178503484
A5: Brazil | B5: BRA | C5: 2003 | D5: 3090.607 | E5: 14.71492 | F5: 11.168 | G5: 180622688
A6: Brazil | B6: BRA | C6: 2004 | D6: 3663.8232 | E6: 6.5971851 | F6: 10.072 | G6: 182675143
A7: Brazil | B7: BRA | C7: 2005 | D7: 4827.7817 | E7: 6.8695372 | F7: 10.551 | G7: 184688101
A8: Brazil | B8: BRA | C8: 2006 | D8: 5934.1447 | E8: 4.1835681 | F8: 9.692 | G8: 186653106
A9: Brazil | B9: BRA | C9: 2007 | D9: 7409.6913 | E9: 3.641273 | F9: 9.28 | G9: 188552320
A10: Brazil | B10: BRA | C10: 2008 | D10: 8908.3318 | E10: 5.6785939 | F10: 8.268 | G10: 190367302
A11: Brazil | B11: BRA | C11: 2009 | D11: 8678.6592 | E11: 4.8880348 | F11: 9.419 | G11: 192079951
A12: Brazil | B12: BRA | C12: 2010 | D12: 11403.282 | E12: 5.0387269 | F12: 8.42 | G12: 193701929
A13: Brazil | B13: BRA | C13: 2011 | D13: 13396.624 | E13: 6.6364496 | F13: 7.578 | G13: 195284734
... A376: United States | B376: USA | C376: 2024 | D376: 86169.664 | E376: 2.9495252 | F376: 4.022 | G376: 340003797

Sheet Analysis
B1: Global Development Indicators — Cross-Country Comparison (2024)
A3: Country | B3: Year | C3: GDP per Capita (US$) | D3: Inflation (%) | E3: Unemployment (%) | F3: Population
A4: Brazil | B4: 2024 | C4: =SUMIFS(Clean_Data!$D:$D,Clean_Data!$A:$A,$A4,Clean_Data!$C:$C,$B4) -> 10310.549 | D4: =SUMIFS(Clean_Data!$E:$E,Clean_Data!$A:$A,$A4,Clean_Data!$C:$C,$B4) -> 4.3674641 | E4: =SUMIFS(Clean_Data!$F:$F,Clean_Data!$A:$A,$A4,Clean_Data!$C:$C,$B4) -> 6.801 | F4: =SUMIFS(Clean_Data!$G:$G,Clean_Data!$A:$A,$A4,Clean_Data!$C:$C,$B4) -> 211998573
A5: China | B5: 2024 | C5: =SUMIFS(Clean_Data!$D:$D,Clean_Data!$A:$A,$A5,Clean_Data!$C:$C,$B5) -> 13293.116 | D5: =SUMIFS(Clean_Data!$E:$E,Clean_Data!$A:$A,$A5,Clean_Data!$C:$C,$B5) -> 0.21812894 | E5: =SUMIFS(Clean_Data!$F:$F,Clean_Data!$A:$A,$A5,Clean_Data!$C:$C,$B5) -> 4.59 | F5: =SUMIFS(Clean_Data!$G:$G,Clean_Data!$A:$A,$A5,Clean_Data!$C:$C,$B5) -> 1408975000
A6: France | B6: 2024 | C6: =SUMIFS(Clean_Data!$D:$D,Clean_Data!$A:$A,$A6,Clean_Data!$C:$C,$B6) -> 46103.084 | D6: =SUMIFS(Clean_Data!$E:$E,Clean_Data!$A:$A,$A6,Clean_Data!$C:$C,$B6) -> 1.997426 | E6: =SUMIFS(Clean_Data!$F:$F,Clean_Data!$A:$A,$A6,Clean_Data!$C:$C,$B6) -> 7.4 | F6: =SUMIFS(Clean_Data!$G:$G,Clean_Data!$A:$A,$A6,Clean_Data!$C:$C,$B6) -> 68551653
A7: Germany | B7: 2024 | C7: =SUMIFS(Clean_Data!$D:$D,Clean_Data!$A:$A,$A7,Clean_Data!$C:$C,$B7) -> 56103.732 | D7: =SUMIFS(Clean_Data!$E:$E,Clean_Data!$A:$A,$A7,Clean_Data!$C:$C,$B7) -> 2.2564981 | E7: =SUMIFS(Clean_Data!$F:$F,Clean_Data!$A:$A,$A7,Clean_Data!$C:$C,$B7) -> 3.4 | F7: =SUMIFS(Clean_Data!$G:$G,Clean_Data!$A:$A,$A7,Clean_Data!$C:$C,$B7) -> 83516593
A8: India | B8: 2024 | C8: =SUMIFS(Clean_Data!$D:$D,Clean_Data!$A:$A,$A8,Clean_Data!$C:$C,$B8) -> 2591.9917 | D8: =SUMIFS(Clean_Data!$E:$E,Clean_Data!$A:$A,$A8,Clean_Data!$C:$C,$B8) -> 4.9530355 | E8: =SUMIFS(Clean_Data!$F:$F,Clean_Data!$A:$A,$A8,Clean_Data!$C:$C,$B8) -> 4.173 | F8: =SUMIFS(Clean_Data!$G:$G,Clean_Data!$A:$A,$A8,Clean_Data!$C:$C,$B8) -> 1450935791
A9: Indonesia | B9: 2024 | C9: =SUMIFS(Clean_Data!$D:$D,Clean_Data!$A:$A,$A9,Clean_Data!$C:$C,$B9) -> 4925.4364 | D9: =SUMIFS(Clean_Data!$E:$E,Clean_Data!$A:$A,$A9,Clean_Data!$C:$C,$B9) -> 2.1815127 | E9: =SUMIFS(Clean_Data!$F:$F,Clean_Data!$A:$A,$A9,Clean_Data!$C:$C,$B9) -> 3.301 | F9: =SUMIFS(Clean_Data!$G:$G,Clean_Data!$A:$A,$A9,Clean_Data!$C:$C,$B9) -> 283487931
A10: Ireland | B10: 2024 | C10: =SUMIFS(Clean_Data!$D:$D,Clean_Data!$A:$A,$A10,Clean_Data!$C:$C,$B10) -> 112894.95 | D10: =SUMIFS(Clean_Data!$E:$E,Clean_Data!$A:$A,$A10,Clean_Data!$C:$C,$B10) -> 2.11345 | E10: =SUMIFS(Clean_Data!$F:$F,Clean_Data!$A:$A,$A10,Clean_Data!$C:$C,$B10) -> 4.3 | F10: =SUMIFS(Clean_Data!$G:$G,Clean_Data!$A:$A,$A10,Clean_Data!$C:$C,$B10) -> 5395790
A11: Italy | B11: 2024 | C11: =SUMIFS(Clean_Data!$D:$D,Clean_Data!$A:$A,$A11,Clean_Data!$C:$C,$B11) -> 40429.622 | D11: =SUMIFS(Clean_Data!$E:$E,Clean_Data!$A:$A,$A11,Clean_Data!$C:$C,$B11) -> 0.98237511 | E11: =SUMIFS(Clean_Data!$F:$F,Clean_Data!$A:$A,$A11,Clean_Data!$C:$C,$B11) -> 6.5 | F11: =SUMIFS(Clean_Data!$G:$G,Clean_Data!$A:$A,$A11,Clean_Data!$C:$C,$B11) -> 58952704
A12: Japan | B12: 2024 | C12: =SUMIFS(Clean_Data!$D:$D,Clean_Data!$A:$A,$A12,Clean_Data!$C:$C,$B12) -> 33797.101 | D12: =SUMIFS(Clean_Data!$E:$E,Clean_Data!$A:$A,$A12,Clean_Data!$C:$C,$B12) -> 2.7385368 | E12: =SUMIFS(Clean_Data!$F:$F,Clean_Data!$A:$A,$A12,Clean_Data!$C:$C,$B12) -> 2.5 | F12: =SUMIFS(Clean_Data!$G:$G,Clean_Data!$A:$A,$A12,Clean_Data!$C:$C,$B12) -> 123975371
A13: Netherlands | B13: 2024 | C13: =SUMIFS(Clean_Data!$D:$D,Clean_Data!$A:$A,$A13,Clean_Data!$C:$C,$B13) -> 67465.321 | D13: =SUMIFS(Clean_Data!$E:$E,Clean_Data!$A:$A,$A13,Clean_Data!$C:$C,$B13) -> 3.346399 | E13: =SUMIFS(Clean_Data!$F:$F,Clean_Data!$A:$A,$A13,Clean_Data!$C:$C,$B13) -> 3.7 | F13: =SUMIFS(Clean_Data!$G:$G,Clean_Data!$A:$A,$A13,Clean_Data!$C:$C,$B13) -> 17993485
A14: Russian Federation | B14: 2024 | C14: =SUMIFS(Clean_Data!$D:$D,Clean_Data!$A:$A,$A14,Clean_Data!$C:$C,$B14) -> 14961.897 | D14: =SUMIFS(Clean_Data!$E:$E,Clean_Data!$A:$A,$A14,Clean_Data!$C:$C,$B14) -> 8.4348641 | E14: =SUMIFS(Clean_Data!$F:$F,Clean_Data!$A:$A,$A14,Clean_Data!$C:$C,$B14) -> 2.43 | F14: =SUMIFS(Clean_Data!$G:$G,Clean_Data!$A:$A,$A14,Clean_Data!$C:$C,$B14) -> 143669648
A15: South Africa | B15: 2024 | C15: =SUMIFS(Clean_Data!$D:$D,Clean_Data!$A:$A,$A15,Clean_Data!$C:$C,$B15) -> 6267.1868 | D15: =SUMIFS(Clean_Data!$E:$E,Clean_Data!$A:$A,$A15,Clean_Data!$C:$C,$B15) -> 4.3611525 | E15: =SUMIFS(Clean_Data!$F:$F,Clean_Data!$A:$A,$A15,Clean_Data!$C:$C,$B15) -> 32.279 | F15: =SUMIFS(Clean_Data!$G:$G,Clean_Data!$A:$A,$A15,Clean_Data!$C:$C,$B15) -> 64007187
... A18: United States | B18: 2024 | C18: =SUMIFS(Clean_Data!$D:$D,Clean_Data!$A:$A,$A18,Clean_Data!$C:$C,$B18) -> 86169.664 | D18: =SUMIFS(Clean_Data!$E:$E,Clean_Data!$A:$A,$A18,Clean_Data!$C:$C,$B18) -> 2.9495252 | E18: =SUMIFS(Clean_Data!$F:$F,Clean_Data!$A:$A,$A18,Clean_Data!$C:$C,$B18) -> 4.022 | F18: =SUMIFS(Clean_Data!$G:$G,Clean_Data!$A:$A,$A18,Clean_Data!$C:$C,$B18) -> 340003797

Sheet Historical_Analysis
A1: Global Development Indicators — Historical Trends (2000–2024)
A3: Country | B3: Year | C3: GDP per Capita (US$) | D3: Inflation (%) | E3: Unemployment (%) | F3: Population | H3: Year | I3: India | J3: China | K3: Germany | L3: Russian Federation | M3: United States | O3: Year | P3: India | Q3: China | R3: Germany | S3: Russian Federation | T3: United States
A4: =Clean_Data!A2 -> Brazil | B4: =Clean_Data!C2 -> 2000 | C4: =Clean_Data!D2 -> 3766.5481 | D4: =Clean_Data!E2 -> 7.0441411 | E4: =Clean_Data!F2 -> 10.889 | F4: =Clean_Data!G2 -> 174018282 | H4: =2000 -> 2000 | I4: =SUMIFS($C$4:$C$378,$A$4:$A$378,I$3,$B$4:$B$378,$H4) -> 442.75022 | J4: =SUMIFS($C$4:$C$378,$A$4:$A$378,J$3,$B$4:$B$378,$H4) -> 969.19951 | K4: =SUMIFS($C$4:$C$378,$A$4:$A$378,K$3,$B$4:$B$378,$H4) -> 23925.856 | L4: =SUMIFS($C$4:$C$378,$A$4:$A$378,L$3,$B$4:$B$378,$H4) -> 1771.5941 | M4: =SUMIFS($C$4:$C$378,$A$4:$A$378,M$3,$B$4:$B$378,$H4) -> 36329.97 | O4: 2000 | P4: =SUMIFS($D$4:$D$378,$A$4:$A$378,P$3,$B$4:$B$378,$O4) -> 4.0094359 | Q4: =SUMIFS($D$4:$D$378,$A$4:$A$378,Q$3,$B$4:$B$378,$O4) -> 0.34781123 | R4: =SUMIFS($D$4:$D$378,$A$4:$A$378,R$3,$B$4:$B$378,$O4) -> 1.4402684 | S4: =SUMIFS($D$4:$D$378,$A$4:$A$378,S$3,$B$4:$B$378,$O4) -> 20.798761 | T4: =SUMIFS($D$4:$D$378,$A$4:$A$378,T$3,$B$4:$B$378,$O4) -> 3.3768573
A5: =Clean_Data!A3 -> Brazil | B5: =Clean_Data!C3 -> 2001 | C5: =Clean_Data!D3 -> 3176.2894 | D5: =Clean_Data!E3 -> 6.840359 | E5: =Clean_Data!F3 -> 10.649 | F5: =Clean_Data!G3 -> 176301203 | H5: =H4+1 -> 2001 | I5: =SUMIFS($C$4:$C$378,$A$4:$A$378,I$3,$B$4:$B$378,$H5) -> 450.3579 | J5: =SUMIFS($C$4:$C$378,$A$4:$A$378,J$3,$B$4:$B$378,$H5) -> 1065.406 | K5: =SUMIFS($C$4:$C$378,$A$4:$A$378,K$3,$B$4:$B$378,$H5) -> 23878.364 | L5: =SUMIFS($C$4:$C$378,$A$4:$A$378,L$3,$B$4:$B$378,$H5) -> 2100.3525 | M5: =SUMIFS($C$4:$C$378,$A$4:$A$378,M$3,$B$4:$B$378,$H5) -> 37133.62 | O5: =O4+1 -> 2001 | P5: =SUMIFS($D$4:$D$378,$A$4:$A$378,P$3,$B$4:$B$378,$O5) -> 3.7792931 | Q5: =SUMIFS($D$4:$D$378,$A$4:$A$378,Q$3,$B$4:$B$378,$O5) -> 0.71912561 | R5: =SUMIFS($D$4:$D$378,$A$4:$A$378,R$3,$B$4:$B$378,$O5) -> 1.9838573 | S5: =SUMIFS($D$4:$D$378,$A$4:$A$378,S$3,$B$4:$B$378,$O5) -> 21.477007 | T5: =SUMIFS($D$4:$D$378,$A$4:$A$378,T$3,$B$4:$B$378,$O5) -> 2.8261711
A6: =Clean_Data!A4 -> Brazil | B6: =Clean_Data!C4 -> 2002 | C6: =Clean_Data!D4 -> 2855.9402 | D6: =Clean_Data!E4 -> 8.4501644 | E6: =Clean_Data!F4 -> 10.641 | F6: =Clean_Data!G4 -> 178503484 | H6: =H5+1 -> 2002 | I6: =SUMIFS($C$4:$C$378,$A$4:$A$378,I$3,$B$4:$B$378,$H6) -> 469.14993 | J6: =SUMIFS($C$4:$C$378,$A$4:$A$378,J$3,$B$4:$B$378,$H6) -> 1163.5596 | K6: =SUMIFS($C$4:$C$378,$A$4:$A$378,K$3,$B$4:$B$378,$H6) -> 25486.594 | L6: =SUMIFS($C$4:$C$378,$A$4:$A$378,L$3,$B$4:$B$378,$H6) -> 2377.5295 | M6: =SUMIFS($C$4:$C$378,$A$4:$A$378,M$3,$B$4:$B$378,$H6) -> 37997.742 | O6: =O5+1 -> 2002 | P6: =SUMIFS($D$4:$D$378,$A$4:$A$378,P$3,$B$4:$B$378,$O6) -> 4.297152 | Q6: =SUMIFS($D$4:$D$378,$A$4:$A$378,Q$3,$B$4:$B$378,$O6) -> -0.7319709 | R6: =SUMIFS($D$4:$D$378,$A$4:$A$378,R$3,$B$4:$B$378,$O6) -> 1.4208062 | S6: =SUMIFS($D$4:$D$378,$A$4:$A$378,S$3,$B$4:$B$378,$O6) -> 15.788731 | T6: =SUMIFS($D$4:$D$378,$A$4:$A$378,T$3,$B$4:$B$378,$O6) -> 1.5860316
A7: =Clean_Data!A5 -> Brazil | B7: =Clean_Data!C5 -> 2003 | C7: =Clean_Data!D5 -> 3090.607 | D7: =Clean_Data!E5 -> 14.71492 | E7: =Clean_Data!F5 -> 11.168 | F7: =Clean_Data!G5 -> 180622688 | H7: =H6+1 -> 2003 | I7: =SUMIFS($C$4:$C$378,$A$4:$A$378,I$3,$B$4:$B$378,$H7) -> 544.14313 | J7: =SUMIFS($C$4:$C$378,$A$4:$A$378,J$3,$B$4:$B$378,$H7) -> 1306.9725 | K7: =SUMIFS($C$4:$C$378,$A$4:$A$378,K$3,$B$4:$B$378,$H7) -> 30711.102 | L7: =SUMIFS($C$4:$C$378,$A$4:$A$378,L$3,$B$4:$B$378,$H7) -> 2975.123 | M7: =SUMIFS($C$4:$C$378,$A$4:$A$378,M$3,$B$4:$B$378,$H7) -> 39490.302 | O7: =O6+1 -> 2003 | P7: =SUMIFS($D$4:$D$378,$A$4:$A$378,P$3,$B$4:$B$378,$O7) -> 3.805859 | Q7: =SUMIFS($D$4:$D$378,$A$4:$A$378,Q$3,$B$4:$B$378,$O7) -> 1.1276035 | R7: =SUMIFS($D$4:$D$378,$A$4:$A$378,R$3,$B$4:$B$378,$O7) -> 1.0342222 | S7: =SUMIFS($D$4:$D$378,$A$4:$A$378,S$3,$B$4:$B$378,$O7) -> 13.663293 | T7: =SUMIFS($D$4:$D$378,$A$4:$A$378,T$3,$B$4:$B$378,$O7) -> 2.270095
A8: =Clean_Data!A6 -> Brazil | B8: =Clean_Data!C6 -> 2004 | C8: =Clean_Data!D6 -> 3663.8232 | D8: =Clean_Data!E6 -> 6.5971851 | E8: =Clean_Data!F6 -> 10.072 | F8: =Clean_Data!G6 -> 182675143 | H8: =H7+1 -> 2004 | I8: =SUMIFS($C$4:$C$378,$A$4:$A$378,I$3,$B$4:$B$378,$H8) -> 624.25883 | J8: =SUMIFS($C$4:$C$378,$A$4:$A$378,J$3,$B$4:$B$378,$H8) -> 1530.9273 | K8: =SUMIFS($C$4:$C$378,$A$4:$A$378,K$3,$B$4:$B$378,$H8) -> 34566.736 | L8: =SUMIFS($C$4:$C$378,$A$4:$A$378,L$3,$B$4:$B$378,$H8) -> 4102.3647 | M8: =SUMIFS($C$4:$C$378,$A$4:$A$378,M$3,$B$4:$B$378,$H8) -> 41724.641 | O8: =O7+1 -> 2004 | P8: =SUMIFS($D$4:$D$378,$A$4:$A$378,P$3,$B$4:$B$378,$O8) -> 3.7672517 | Q8: =SUMIFS($D$4:$D$378,$A$4:$A$378,Q$3,$B$4:$B$378,$O8) -> 3.8246374 | R8: =SUMIFS($D$4:$D$378,$A$4:$A$378,R$3,$B$4:$B$378,$O8) -> 1.665737 | S8: =SUMIFS($D$4:$D$378,$A$4:$A$378,S$3,$B$4:$B$378,$O8) -> 10.888616 | T8: =SUMIFS($D$4:$D$378,$A$4:$A$378,T$3,$B$4:$B$378,$O8) -> 2.6772367
A9: =Clean_Data!A7 -> Brazil | B9: =Clean_Data!C7 -> 2005 | C9: =Clean_Data!D7 -> 4827.7817 | D9: =Clean_Data!E7 -> 6.8695372 | E9: =Clean_Data!F7 -> 10.551 | F9: =Clean_Data!G7 -> 184688101 | H9: =H8+1 -> 2005 | I9: =SUMIFS($C$4:$C$378,$A$4:$A$378,I$3,$B$4:$B$378,$H9) -> 710.48808 | J9: =SUMIFS($C$4:$C$378,$A$4:$A$378,J$3,$B$4:$B$378,$H9) -> 1777.645 | K9: =SUMIFS($C$4:$C$378,$A$4:$A$378,K$3,$B$4:$B$378,$H9) -> 35084.436 | L9: =SUMIFS($C$4:$C$378,$A$4:$A$378,L$3,$B$4:$B$378,$H9) -> 5323.4551 | M9: =SUMIFS($C$4:$C$378,$A$4:$A$378,M$3,$B$4:$B$378,$H9) -> 44123.4 | O9: =O8+1 -> 2005 | P9: =SUMIFS($D$4:$D$378,$A$4:$A$378,P$3,$B$4:$B$378,$O9) -> 4.2463436 | Q9: =SUMIFS($D$4:$D$378,$A$4:$A$378,Q$3,$B$4:$B$378,$O9) -> 1.7764141 | R9: =SUMIFS($D$4:$D$378,$A$4:$A$378,R$3,$B$4:$B$378,$O9) -> 1.5469111 | S9: =SUMIFS($D$4:$D$378,$A$4:$A$378,S$3,$B$4:$B$378,$O9) -> 12.685304 | T9: =SUMIFS($D$4:$D$378,$A$4:$A$378,T$3,$B$4:$B$378,$O9) -> 3.3927468
A10: =Clean_Data!A8 -> Brazil | B10: =Clean_Data!C8 -> 2006 | C10: =Clean_Data!D8 -> 5934.1447 | D10: =Clean_Data!E8 -> 4.1835681 | E10: =Clean_Data!F8 -> 9.692 | F10: =Clean_Data!G8 -> 186653106 | H10: =H9+1 -> 2006 | I10: =SUMIFS($C$4:$C$378,$A$4:$A$378,I$3,$B$4:$B$378,$H10) -> 801.66835 | J10: =SUMIFS($C$4:$C$378,$A$4:$A$378,J$3,$B$4:$B$378,$H10) -> 2129.257 | K10: =SUMIFS($C$4:$C$378,$A$4:$A$378,K$3,$B$4:$B$378,$H10) -> 36980.335 | L10: =SUMIFS($C$4:$C$378,$A$4:$A$378,L$3,$B$4:$B$378,$H10) -> 6920.1997 | M10: =SUMIFS($C$4:$C$378,$A$4:$A$378,M$3,$B$4:$B$378,$H10) -> 46301.988 | O10: =O9+1 -> 2006 | P10: =SUMIFS($D$4:$D$378,$A$4:$A$378,P$3,$B$4:$B$378,$O10) -> 5.7965234 | Q10: =SUMIFS($D$4:$D$378,$A$4:$A$378,Q$3,$B$4:$B$378,$O10) -> 1.649431 | R10: =SUMIFS($D$4:$D$378,$A$4:$A$378,R$3,$B$4:$B$378,$O10) -> 1.5774264 | S10: =SUMIFS($D$4:$D$378,$A$4:$A$378,S$3,$B$4:$B$378,$O10) -> 9.6686545 | T10: =SUMIFS($D$4:$D$378,$A$4:$A$378,T$3,$B$4:$B$378,$O10) -> 3.2259441
A11: =Clean_Data!A9 -> Brazil | B11: =Clean_Data!C9 -> 2007 | C11: =Clean_Data!D9 -> 7409.6913 | D11: =Clean_Data!E9 -> 3.641273 | E11: =Clean_Data!F9 -> 9.28 | F11: =Clean_Data!G9 -> 188552320 | H11: =H10+1 -> 2007 | I11: =SUMIFS($C$4:$C$378,$A$4:$A$378,I$3,$B$4:$B$378,$H11) -> 1021.8871 | J11: =SUMIFS($C$4:$C$378,$A$4:$A$378,J$3,$B$4:$B$378,$H11) -> 2734.7271 | K11: =SUMIFS($C$4:$C$378,$A$4:$A$378,K$3,$B$4:$B$378,$H11) -> 42350.922 | L11: =SUMIFS($C$4:$C$378,$A$4:$A$378,L$3,$B$4:$B$378,$H11) -> 9101.2393 | M11: =SUMIFS($C$4:$C$378,$A$4:$A$378,M$3,$B$4:$B$378,$H11) -> 48050.227 | O11: =O10+1 -> 2007 | P11: =SUMIFS($D$4:$D$378,$A$4:$A$378,P$3,$B$4:$B$378,$O11) -> 6.3728814 | Q11: =SUMIFS($D$4:$D$378,$A$4:$A$378,Q$3,$B$4:$B$378,$O11) -> 4.8167677 | R11: =SUMIFS($D$4:$D$378,$A$4:$A$378,R$3,$B$4:$B$378,$O11) -> 2.298344 | S11: =SUMIFS($D$4:$D$378,$A$4:$A$378,S$3,$B$4:$B$378,$O11) -> 9.0072987 | T11: =SUMIFS($D$4:$D$378,$A$4:$A$378,T$3,$B$4:$B$378,$O11) -> 2.8526725
A12: =Clean_Data!A10 -> Brazil | B12: =Clean_Data!C10 -> 2008 | C12: =Clean_Data!D10 -> 8908.3318 | D12: =Clean_Data!E10 -> 5.6785939 | E12: =Clean_Data!F10 -> 8.268 | F12: =Clean_Data!G10 -> 190367302 | H12: =H11+1 -> 2008 | I12: =SUMIFS($C$4:$C$378,$A$4:$A$378,I$3,$B$4:$B$378,$H12) -> 992.51958 | J12: =SUMIFS($C$4:$C$378,$A$4:$A$378,J$3,$B$4:$B$378,$H12) -> 3523.443 | K12: =SUMIFS($C$4:$C$378,$A$4:$A$378,K$3,$B$4:$B$378,$H12) -> 46379.165 | L12: =SUMIFS($C$4:$C$378,$A$4:$A$378,L$3,$B$4:$B$378,$H12) -> 11635.284 | M12: =SUMIFS($C$4:$C$378,$A$4:$A$378,M$3,$B$4:$B$378,$H12) -> 48570.059 | O12: =O11+1 -> 2008 | P12: =SUMIFS($D$4:$D$378,$A$4:$A$378,P$3,$B$4:$B$378,$O12) -> 8.349267 | Q12: =SUMIFS($D$4:$D$378,$A$4:$A$378,Q$3,$B$4:$B$378,$O12) -> 5.9252514 | R12: =SUMIFS($D$4:$D$378,$A$4:$A$378,R$3,$B$4:$B$378,$O12) -> 2.6283798 | S12: =SUMIFS($D$4:$D$378,$A$4:$A$378,S$3,$B$4:$B$378,$O12) -> 14.110768 | T12: =SUMIFS($D$4:$D$378,$A$4:$A$378,T$3,$B$4:$B$378,$O12) -> 3.8391003
A13: =Clean_Data!A11 -> Brazil | B13: =Clean_Data!C11 -> 2009 | C13: =Clean_Data!D11 -> 8678.6592 | D13: =Clean_Data!E11 -> 4.8880348 | E13: =Clean_Data!F11 -> 9.419 | F13: =Clean_Data!G11 -> 192079951 | H13: =H12+1 -> 2009 | I13: =SUMIFS($C$4:$C$378,$A$4:$A$378,I$3,$B$4:$B$378,$H13) -> 1094.9497 | J13: =SUMIFS($C$4:$C$378,$A$4:$A$378,J$3,$B$4:$B$378,$H13) -> 3898.2446 | K13: =SUMIFS($C$4:$C$378,$A$4:$A$378,K$3,$B$4:$B$378,$H13) -> 42471.887 | L13: =SUMIFS($C$4:$C$378,$A$4:$A$378,L$3,$B$4:$B$378,$H13) -> 8562.8242 | M13: =SUMIFS($C$4:$C$378,$A$4:$A$378,M$3,$B$4:$B$378,$H13) -> 47194.95 | O13: =O12+1 -> 2009 | P13: =SUMIFS($D$4:$D$378,$A$4:$A$378,P$3,$B$4:$B$378,$O13) -> 10.882353 | Q13: =SUMIFS($D$4:$D$378,$A$4:$A$378,Q$3,$B$4:$B$378,$O13) -> -0.72816525 | R13: =SUMIFS($D$4:$D$378,$A$4:$A$378,R$3,$B$4:$B$378,$O13) -> 0.31273901 | S13: =SUMIFS($D$4:$D$378,$A$4:$A$378,S$3,$B$4:$B$378,$O13) -> 11.64733 | T13: =SUMIFS($D$4:$D$378,$A$4:$A$378,T$3,$B$4:$B$378,$O13) -> -0.35554627
A14: =Clean_Data!A12 -> Brazil | B14: =Clean_Data!C12 -> 2010 | C14: =Clean_Data!D12 -> 11403.282 | D14: =Clean_Data!E12 -> 5.0387269 | E14: =Clean_Data!F12 -> 8.42 | F14: =Clean_Data!G12 -> 193701929 | H14: =H13+1 -> 2010 | I14: =SUMIFS($C$4:$C$378,$A$4:$A$378,I$3,$B$4:$B$378,$H14) -> 1347.5194 | J14: =SUMIFS($C$4:$C$378,$A$4:$A$378,J$3,$B$4:$B$378,$H14) -> 4629.2455 | K14: =SUMIFS($C$4:$C$378,$A$4:$A$378,K$3,$B$4:$B$378,$H14) -> 42396.967 | L14: =SUMIFS($C$4:$C$378,$A$4:$A$378,L$3,$B$4:$B$378,$H14) -> 10674.99 | M14: =SUMIFS($C$4:$C$378,$A$4:$A$378,M$3,$B$4:$B$378,$H14) -> 48642.631 | O14: =O13+1 -> 2010 | P14: =SUMIFS($D$4:$D$378,$A$4:$A$378,P$3,$B$4:$B$378,$O14) -> 11.98939 | Q14: =SUMIFS($D$4:$D$378,$A$4:$A$378,Q$3,$B$4:$B$378,$O14) -> 3.1753248 | R14: =SUMIFS($D$4:$D$378,$A$4:$A$378,R$3,$B$4:$B$378,$O14) -> 1.1038104 | S14: =SUMIFS($D$4:$D$378,$A$4:$A$378,S$3,$B$4:$B$378,$O14) -> 6.8493923 | T14: =SUMIFS($D$4:$D$378,$A$4:$A$378,T$3,$B$4:$B$378,$O14) -> 1.6400434
A15: =Clean_Data!A13 -> Brazil | B15: =Clean_Data!C13 -> 2011 | C15: =Clean_Data!D13 -> 13396.624 | D15: =Clean_Data!E13 -> 6.6364496 | E15: =Clean_Data!F13 -> 7.578 | F15: =Clean_Data!G13 -> 195284734 | H15: =H14+1 -> 2011 | I15: =SUMIFS($C$4:$C$378,$A$4:$A$378,I$3,$B$4:$B$378,$H15) -> 1445.4613 | J15: =SUMIFS($C$4:$C$378,$A$4:$A$378,J$3,$B$4:$B$378,$H15) -> 5703.7603 | K15: =SUMIFS($C$4:$C$378,$A$4:$A$378,K$3,$B$4:$B$378,$H15) -> 47630.976 | L15: =SUMIFS($C$4:$C$378,$A$4:$A$378,L$3,$B$4:$B$378,$H15) -> 14305.332 | M15: =SUMIFS($C$4:$C$378,$A$4:$A$378,M$3,$B$4:$B$378,$H15) -> 50024.881 | O15: =O14+1 -> 2011 | P15: =SUMIFS($D$4:$D$378,$A$4:$A$378,P$3,$B$4:$B$378,$O15) -> 8.9117934 | Q15: =SUMIFS($D$4:$D$378,$A$4:$A$378,Q$3,$B$4:$B$378,$O15) -> 5.5538989 | R15: =SUMIFS($D$4:$D$378,$A$4:$A$378,R$3,$B$4:$B$378,$O15) -> 2.0751728 | S15: =SUMIFS($D$4:$D$378,$A$4:$A$378,S$3,$B$4:$B$378,$O15) -> 8.4404649 | T15: =SUMIFS($D$4:$D$378,$A$4:$A$378,T$3,$B$4:$B$378,$O15) -> 3.1568416
A16: =Clean_Data!A14 -> Brazil | B16: =Clean_Data!C14 -> 2012 | C16: =Clean_Data!D14 -> 12521.721 | D16: =Clean_Data!E14 -> 5.4034991 | E16: =Clean_Data!F14 -> 7.251 | F16: =Clean_Data!G14 -> 196876111 | H16: =H15+1 -> 2012 | I16: =SUMIFS($C$4:$C$378,$A$4:$A$378,I$3,$B$4:$B$378,$H16) -> 1429.322 | J16: =SUMIFS($C$4:$C$378,$A$4:$A$378,J$3,$B$4:$B$378,$H16) -> 6405.0574 | K16: =SUMIFS($C$4:$C$378,$A$4:$A$378,K$3,$B$4:$B$378,$H16) -> 44718.016 | L16: =SUMIFS($C$4:$C$378,$A$4:$A$378,L$3,$B$4:$B$378,$H16) -> 15401.852 | M16: =SUMIFS($C$4:$C$378,$A$4:$A$378,M$3,$B$4:$B$378,$H16) -> 51708.394 | O16: =O15+1 -> 2012 | P16: =SUMIFS($D$4:$D$378,$A$4:$A$378,P$3,$B$4:$B$378,$O16) -> 9.4789969 | Q16: =SUMIFS($D$4:$D$378,$A$4:$A$378,Q$3,$B$4:$B$378,$O16) -> 2.6195243 | R16: =SUMIFS($D$4:$D$378,$A$4:$A$378,R$3,$B$4:$B$378,$O16) -> 2.0084888 | S16: =SUMIFS($D$4:$D$378,$A$4:$A$378,S$3,$B$4:$B$378,$O16) -> 5.074743 | T16: =SUMIFS($D$4:$D$378,$A$4:$A$378,T$3,$B$4:$B$378,$O16) -> 2.0693373
... A28: =Clean_Data!A26 -> Brazil | B28: =Clean_Data!C26 -> 2024 | C28: =Clean_Data!D26 -> 10310.549 | D28: =Clean_Data!E26 -> 4.3674641 | E28: =Clean_Data!F26 -> 6.801 | F28: =Clean_Data!G26 -> 211998573 | H28: =H27+1 -> 2024 | I28: =SUMIFS($C$4:$C$378,$A$4:$A$378,I$3,$B$4:$B$378,$H28) -> 2591.9917 | J28: =SUMIFS($C$4:$C$378,$A$4:$A$378,J$3,$B$4:$B$378,$H28) -> 13293.116 | K28: =SUMIFS($C$4:$C$378,$A$4:$A$378,K$3,$B$4:$B$378,$H28) -> 56103.732 | L28: =SUMIFS($C$4:$C$378,$A$4:$A$378,L$3,$B$4:$B$378,$H28) -> 14961.897 | M28: =SUMIFS($C$4:$C$378,$A$4:$A$378,M$3,$B$4:$B$378,$H28) -> 86169.664 | O28: =O27+1 -> 2024 | P28: =SUMIFS($D$4:$D$378,$A$4:$A$378,P$3,$B$4:$B$378,$O28) -> 4.9530355 | Q28: =SUMIFS($D$4:$D$378,$A$4:$A$378,Q$3,$B$4:$B$378,$O28) -> 0.21812894 | R28: =SUMIFS($D$4:$D$378,$A$4:$A$378,R$3,$B$4:$B$378,$O28) -> 2.2564981 | S28: =SUMIFS($D$4:$D$378,$A$4:$A$378,S$3,$B$4:$B$378,$O28) -> 8.4348641 | T28: =SUMIFS($D$4:$D$378,$A$4:$A$378,T$3,$B$4:$B$378,$O28) -> 2.9495252
A29: =Clean_Data!A27 -> China | B29: =Clean_Data!C27 -> 2000 | C29: =Clean_Data!D27 -> 969.19951 | D29: =Clean_Data!E27 -> 0.34781123 | E29: =Clean_Data!F27 -> 3.26 | F29: =Clean_Data!G27 -> 1262645000
A30: =Clean_Data!A28 -> China | B30: =Clean_Data!C28 -> 2001 | C30: =Clean_Data!D28 -> 1065.406 | D30: =Clean_Data!E28 -> 0.71912561 | E30: =Clean_Data!F28 -> 3.8 | F30: =Clean_Data!G28 -> 1271850000
A31: =Clean_Data!A29 -> China | B31: =Clean_Data!C29 -> 2002 | C31: =Clean_Data!D29 -> 1163.5596 | D31: =Clean_Data!E29 -> -0.7319709 | E31: =Clean_Data!F29 -> 4.24 | F31: =Clean_Data!G29 -> 1280400000 | H31: Year | I31: India | J31: China | K31: Germany | L31: Russian Federation | M31: United States | O31: Year | P31: India | Q31: China | R31: Germany | S31: Russian Federation | T31: United States
A32: =Clean_Data!A30 -> China | B32: =Clean_Data!C30 -> 2003 | C32: =Clean_Data!D30 -> 1306.9725 | D32: =Clean_Data!E30 -> 1.1276035 | E32: =Clean_Data!F30 -> 4.58 | F32: =Clean_Data!G30 -> 1288400000 | H32: =2000 -> 2000 | I32: =SUMIFS($F$4:$F$378,$A$4:$A$378,I$31,$B$4:$B$378,$H32) -> 1057922733 | J32: =SUMIFS($F$4:$F$378,$A$4:$A$378,J$31,$B$4:$B$378,$H32) -> 1262645000 | K32: =SUMIFS($F$4:$F$378,$A$4:$A$378,K$31,$B$4:$B$378,$H32) -> 82211508 | L32: =SUMIFS($F$4:$F$378,$A$4:$A$378,L$31,$B$4:$B$378,$H32) -> 146596869 | M32: =SUMIFS($F$4:$F$378,$A$4:$A$378,M$31,$B$4:$B$378,$H32) -> 282162411 | O32: =2000 -> 2000 | P32: =SUMIFS($E$4:$E$378,$A$4:$A$378,P$31,$B$4:$B$378,$O32) -> 7.589 | Q32: =SUMIFS($E$4:$E$378,$A$4:$A$378,Q$31,$B$4:$B$378,$O32) -> 3.26 | R32: =SUMIFS($E$4:$E$378,$A$4:$A$378,R$31,$B$4:$B$378,$O32) -> 7.917 | S32: =SUMIFS($E$4:$E$378,$A$4:$A$378,S$31,$B$4:$B$378,$O32) -> 10.581 | T32: =SUMIFS($E$4:$E$378,$A$4:$A$378,T$31,$B$4:$B$378,$O32) -> 3.992
A33: =Clean_Data!A31 -> China | B33: =Clean_Data!C31 -> 2004 | C33: =Clean_Data!D31 -> 1530.9273 | D33: =Clean_Data!E31 -> 3.8246374 | E33: =Clean_Data!F31 -> 4.49 | F33: =Clean_Data!G31 -> 1296075000 | H33: =H32+1 -> 2001 | I33: =SUMIFS($F$4:$F$378,$A$4:$A$378,I$31,$B$4:$B$378,$H33) -> 1077898575 | J33: =SUMIFS($F$4:$F$378,$A$4:$A$378,J$31,$B$4:$B$378,$H33) -> 1271850000 | K33: =SUMIFS($F$4:$F$378,$A$4:$A$378,K$31,$B$4:$B$378,$H33) -> 82349925 | L33: =SUMIFS($F$4:$F$378,$A$4:$A$378,L$31,$B$4:$B$378,$H33) -> 145976482 | M33: =SUMIFS($F$4:$F$378,$A$4:$A$378,M$31,$B$4:$B$378,$H33) -> 284968955 | O33: =O32+1 -> 2001 | P33: =SUMIFS($E$4:$E$378,$A$4:$A$378,P$31,$B$4:$B$378,$O33) -> 7.611 | Q33: =SUMIFS($E$4:$E$378,$A$4:$A$378,Q$31,$B$4:$B$378,$O33) -> 3.8 | R33: =SUMIFS($E$4:$E$378,$A$4:$A$378,R$31,$B$4:$B$378,$O33) -> 7.773 | S33: =SUMIFS($E$4:$E$378,$A$4:$A$378,S$31,$B$4:$B$378,$O33) -> 8.978 | T33: =SUMIFS($E$4:$E$378,$A$4:$A$378,T$31,$B$4:$B$378,$O33) -> 4.731
A34: =Clean_Data!A32 -> China | B34: =Clean_Data!C32 -> 2005 | C34: =Clean_Data!D32 -> 1777.645 | D34: =Clean_Data!E32 -> 1.7764141 | E34: =Clean_Data!F32 -> 4.52 | F34: =Clean_Data!G32 -> 1303720000 | H34: =H33+1 -> 2002 | I34: =SUMIFS($F$4:$F$378,$A$4:$A$378,I$31,$B$4:$B$378,$H34) -> 1097600380 | J34: =SUMIFS($F$4:$F$378,$A$4:$A$378,J$31,$B$4:$B$378,$H34) -> 1280400000 | K34: =SUMIFS($F$4:$F$378,$A$4:$A$378,K$31,$B$4:$B$378,$H34) -> 82488495 | L34: =SUMIFS($F$4:$F$378,$A$4:$A$378,L$31,$B$4:$B$378,$H34) -> 145306497 | M34: =SUMIFS($F$4:$F$378,$A$4:$A$378,M$31,$B$4:$B$378,$H34) -> 287625193 | O34: =O33+1 -> 2002 | P34: =SUMIFS($E$4:$E$378,$A$4:$A$378,P$31,$B$4:$B$378,$O34) -> 7.681 | Q34: =SUMIFS($E$4:$E$378,$A$4:$A$378,Q$31,$B$4:$B$378,$O34) -> 4.24 | R34: =SUMIFS($E$4:$E$378,$A$4:$A$378,R$31,$B$4:$B$378,$O34) -> 8.482 | S34: =SUMIFS($E$4:$E$378,$A$4:$A$378,S$31,$B$4:$B$378,$O34) -> 7.875 | T34: =SUMIFS($E$4:$E$378,$A$4:$A$378,T$31,$B$4:$B$378,$O34) -> 5.783
A35: =Clean_Data!A33 -> China | B35: =Clean_Data!C33 -> 2006 | C35: =Clean_Data!D33 -> 2129.257 | D35: =Clean_Data!E33 -> 1.649431 | E35: =Clean_Data!F33 -> 4.43 | F35: =Clean_Data!G33 -> 1311020000 | H35: =H34+1 -> 2003 | I35: =SUMIFS($F$4:$F$378,$A$4:$A$378,I$31,$B$4:$B$378,$H35) -> 1116803006 | J35: =SUMIFS($F$4:$F$378,$A$4:$A$378,J$31,$B$4:$B$378,$H35) -> 1288400000 | K35: =SUMIFS($F$4:$F$378,$A$4:$A$378,K$31,$B$4:$B$378,$H35) -> 82534176 | L35: =SUMIFS($F$4:$F$378,$A$4:$A$378,L$31,$B$4:$B$378,$H35) -> 144648618 | M35: =SUMIFS($F$4:$F$378,$A$4:$A$378,M$31,$B$4:$B$378,$H35) -> 290107933 | O35: =O34+1 -> 2003 | P35: =SUMIFS($E$4:$E$378,$A$4:$A$378,P$31,$B$4:$B$378,$O35) -> 7.633 | Q35: =SUMIFS($E$4:$E$378,$A$4:$A$378,Q$31,$B$4:$B$378,$O35) -> 4.58 | R35: =SUMIFS($E$4:$E$378,$A$4:$A$378,R$31,$B$4:$B$378,$O35) -> 9.779 | S35: =SUMIFS($E$4:$E$378,$A$4:$A$378,S$31,$B$4:$B$378,$O35) -> 8.21 | T35: =SUMIFS($E$4:$E$378,$A$4:$A$378,T$31,$B$4:$B$378,$O35) -> 5.989
A36: =Clean_Data!A34 -> China | B36: =Clean_Data!C34 -> 2007 | C36: =Clean_Data!D34 -> 2734.7271 | D36: =Clean_Data!E34 -> 4.8167677 | E36: =Clean_Data!F34 -> 4.35 | F36: =Clean_Data!G34 -> 1317885000 | H36: =H35+1 -> 2004 | I36: =SUMIFS($F$4:$F$378,$A$4:$A$378,I$31,$B$4:$B$378,$H36) -> 1135991513 | J36: =SUMIFS($F$4:$F$378,$A$4:$A$378,J$31,$B$4:$B$378,$H36) -> 1296075000 | K36: =SUMIFS($F$4:$F$378,$A$4:$A$378,K$31,$B$4:$B$378,$H36) -> 82516260 | L36: =SUMIFS($F$4:$F$378,$A$4:$A$378,L$31,$B$4:$B$378,$H36) -> 144067316 | M36: =SUMIFS($F$4:$F$378,$A$4:$A$378,M$31,$B$4:$B$378,$H36) -> 292805298 | O36: =O35+1 -> 2004 | P36: =SUMIFS($E$4:$E$378,$A$4:$A$378,P$31,$B$4:$B$378,$O36) -> 7.598 | Q36: =SUMIFS($E$4:$E$378,$A$4:$A$378,Q$31,$B$4:$B$378,$O36) -> 4.49 | R36: =SUMIFS($E$4:$E$378,$A$4:$A$378,R$31,$B$4:$B$378,$O36) -> 10.727 | S36: =SUMIFS($E$4:$E$378,$A$4:$A$378,S$31,$B$4:$B$378,$O36) -> 7.763 | T36: =SUMIFS($E$4:$E$378,$A$4:$A$378,T$31,$B$4:$B$378,$O36) -> 5.529
A37: =Clean_Data!A35 -> China | B37: =Clean_Data!C35 -> 2008 | C37: =Clean_Data!D35 -> 3523.443 | D37: =Clean_Data!E35 -> 5.9252514 | E37: =Clean_Data!F35 -> 4.59 | F37: =Clean_Data!G35 -> 1324655000 | H37: =H36+1 -> 2005 | I37: =SUMIFS($F$4:$F$378,$A$4:$A$378,I$31,$B$4:$B$378,$H37) -> 1154676322 | J37: =SUMIFS($F$4:$F$378,$A$4:$A$378,J$31,$B$4:$B$378,$H37) -> 1303720000 | K37: =SUMIFS($F$4:$F$378,$A$4:$A$378,K$31,$B$4:$B$378,$H37) -> 82469422 | L37: =SUMIFS($F$4:$F$378,$A$4:$A$378,L$31,$B$4:$B$378,$H37) -> 143518814 | M37: =SUMIFS($F$4:$F$378,$A$4:$A$378,M$31,$B$4:$B$378,$H37) -> 295516599 | O37: =O36+1 -> 2005 | P37: =SUMIFS($E$4:$E$378,$A$4:$A$378,P$31,$B$4:$B$378,$O37) -> 7.551 | Q37: =SUMIFS($E$4:$E$378,$A$4:$A$378,Q$31,$B$4:$B$378,$O37) -> 4.52 | R37: =SUMIFS($E$4:$E$378,$A$4:$A$378,R$31,$B$4:$B$378,$O37) -> 11.193 | S37: =SUMIFS($E$4:$E$378,$A$4:$A$378,S$31,$B$4:$B$378,$O37) -> 7.124 | T37: =SUMIFS($E$4:$E$378,$A$4:$A$378,T$31,$B$4:$B$378,$O37) -> 5.084
A38: =Clean_Data!A36 -> China | B38: =Clean_Data!C36 -> 2009 | C38: =Clean_Data!D36 -> 3898.2446 | D38: =Clean_Data!E36 -> -0.72816525 | E38: =Clean_Data!F36 -> 4.72 | F38: =Clean_Data!G36 -> 1331260000 | H38: =H37+1 -> 2006 | I38: =SUMIFS($F$4:$F$378,$A$4:$A$378,I$31,$B$4:$B$378,$H38) -> 1172878890 | J38: =SUMIFS($F$4:$F$378,$A$4:$A$378,J$31,$B$4:$B$378,$H38) -> 1311020000 | K38: =SUMIFS($F$4:$F$378,$A$4:$A$378,K$31,$B$4:$B$378,$H38) -> 82376451 | L38: =SUMIFS($F$4:$F$378,$A$4:$A$378,L$31,$B$4:$B$378,$H38) -> 143049637 | M38: =SUMIFS($F$4:$F$378,$A$4:$A$378,M$31,$B$4:$B$378,$H38) -> 298379912 | O38: =O37+1 -> 2006 | P38: =SUMIFS($E$4:$E$378,$A$4:$A$378,P$31,$B$4:$B$378,$O38) -> 7.553 | Q38: =SUMIFS($E$4:$E$378,$A$4:$A$378,Q$31,$B$4:$B$378,$O38) -> 4.43 | R38: =SUMIFS($E$4:$E$378,$A$4:$A$378,R$31,$B$4:$B$378,$O38) -> 10.277 | S38: =SUMIFS($E$4:$E$378,$A$4:$A$378,S$31,$B$4:$B$378,$O38) -> 7.055 | T38: =SUMIFS($E$4:$E$378,$A$4:$A$378,T$31,$B$4:$B$378,$O38) -> 4.623
A39: =Clean_Data!A37 -> China | B39: =Clean_Data!C37 -> 2010 | C39: =Clean_Data!D37 -> 4629.2455 | D39: =Clean_Data!E37 -> 3.1753248 | E39: =Clean_Data!F37 -> 4.53 | F39: =Clean_Data!G37 -> 1337705000 | H39: =H38+1 -> 2007 | I39: =SUMIFS($F$4:$F$378,$A$4:$A$378,I$31,$B$4:$B$378,$H39) -> 1190676021 | J39: =SUMIFS($F$4:$F$378,$A$4:$A$378,J$31,$B$4:$B$378,$H39) -> 1317885000 | K39: =SUMIFS($F$4:$F$378,$A$4:$A$378,K$31,$B$4:$B$378,$H39) -> 82266372 | L39: =SUMIFS($F$4:$F$378,$A$4:$A$378,L$31,$B$4:$B$378,$H39) -> 142805114 | M39: =SUMIFS($F$4:$F$378,$A$4:$A$378,M$31,$B$4:$B$378,$H39) -> 301231207 | O39: =O38+1 -> 2007 | P39: =SUMIFS($E$4:$E$378,$A$4:$A$378,P$31,$B$4:$B$378,$O39) -> 7.562 | Q39: =SUMIFS($E$4:$E$378,$A$4:$A$378,Q$31,$B$4:$B$378,$O39) -> 4.35 | R39: =SUMIFS($E$4:$E$378,$A$4:$A$378,R$31,$B$4:$B$378,$O39) -> 8.732 | S39: =SUMIFS($E$4:$E$378,$A$4:$A$378,S$31,$B$4:$B$378,$O39) -> 6.002 | T39: =SUMIFS($E$4:$E$378,$A$4:$A$378,T$31,$B$4:$B$378,$O39) -> 4.622
A40: =Clean_Data!A38 -> China | B40: =Clean_Data!C38 -> 2011 | C40: =Clean_Data!D38 -> 5703.7603 | D40: =Clean_Data!E38 -> 5.5538989 | E40: =Clean_Data!F38 -> 4.55 | F40: =Clean_Data!G38 -> 1345035000 | H40: =H39+1 -> 2008 | I40: =SUMIFS($F$4:$F$378,$A$4:$A$378,I$31,$B$4:$B$378,$H40) -> 1207930964 | J40: =SUMIFS($F$4:$F$378,$A$4:$A$378,J$31,$B$4:$B$378,$H40) -> 1324655000 | K40: =SUMIFS($F$4:$F$378,$A$4:$A$378,K$31,$B$4:$B$378,$H40) -> 82110097 | L40: =SUMIFS($F$4:$F$378,$A$4:$A$378,L$31,$B$4:$B$378,$H40) -> 142742366 | M40: =SUMIFS($F$4:$F$378,$A$4:$A$378,M$31,$B$4:$B$378,$H40) -> 304093966 | O40: =O39+1 -> 2008 | P40: =SUMIFS($E$4:$E$378,$A$4:$A$378,P$31,$B$4:$B$378,$O40) -> 7.629 | Q40: =SUMIFS($E$4:$E$378,$A$4:$A$378,Q$31,$B$4:$B$378,$O40) -> 4.59 | R40: =SUMIFS($E$4:$E$378,$A$4:$A$378,R$31,$B$4:$B$378,$O40) -> 7.508 | S40: =SUMIFS($E$4:$E$378,$A$4:$A$378,S$31,$B$4:$B$378,$O40) -> 6.205 | T40: =SUMIFS($E$4:$E$378,$A$4:$A$378,T$31,$B$4:$B$378,$O40) -> 5.784
A41: =Clean_Data!A39 -> China | B41: =Clean_Data!C39 -> 2012 | C41: =Clean_Data!D39 -> 6405.0574 | D41: =Clean_Data!E39 -> 2.6195243 | E41: =Clean_Data!F39 -> 4.58 | F41: =Clean_Data!G39 -> 1354190000 | H41: =H40+1 -> 2009 | I41: =SUMIFS($F$4:$F$378,$A$4:$A$378,I$31,$B$4:$B$378,$H41) -> 1225524753 | J41: =SUMIFS($F$4:$F$378,$A$4:$A$378,J$31,$B$4:$B$378,$H41) -> 1331260000 | K41: =SUMIFS($F$4:$F$378,$A$4:$A$378,K$31,$B$4:$B$378,$H41) -> 81902307 | L41: =SUMIFS($F$4:$F$378,$A$4:$A$378,L$31,$B$4:$B$378,$H41) -> 142785348 | M41: =SUMIFS($F$4:$F$378,$A$4:$A$378,M$31,$B$4:$B$378,$H41) -> 306771529 | O41: =O40+1 -> 2009 | P41: =SUMIFS($E$4:$E$378,$A$4:$A$378,P$31,$B$4:$B$378,$O41) -> 7.636 | Q41: =SUMIFS($E$4:$E$378,$A$4:$A$378,Q$31,$B$4:$B$378,$O41) -> 4.72 | R41: =SUMIFS($E$4:$E$378,$A$4:$A$378,R$31,$B$4:$B$378,$O41) -> 7.88 | S41: =SUMIFS($E$4:$E$378,$A$4:$A$378,S$31,$B$4:$B$378,$O41) -> 8.301 | T41: =SUMIFS($E$4:$E$378,$A$4:$A$378,T$31,$B$4:$B$378,$O41) -> 9.254
